Workbook

Sheet IOC Tracker
A1: IOC Tracker
A2: LIVE MALICIOUS INDICATORS (defanged) pulled 2026-10-13 from abuse.ch ThreatFox, MalwareBazaar and Feodo Tracker. Click any Source cell to verify on the feed before blocking. Yellow cells are editable; Status (col N) updates from the Expiry / Review date. Blank rows at the bottom are for your own IOCs.
A4: ID | B4: Indicator (defanged) | C4: IOC Type | D4: Threat Actor / Malware Family | E4: MITRE ATT&CK Technique | F4: Confidence | G4: Severity | H4: First Seen | I4: Last Seen | J4: Source | K4: Action Taken | L4: Expiry / Review Date | M4: Notes | N4: Status
A5: IOC-001 | B5: hxxps://x5u[.]6r6r6[.]org/x0 | C5: URL | D5: Vidar | E5: T1071 - Application Layer Protocol | F5: High | G5: High | H5: 46308 | I5: 46308 | J5: ThreatFox #1963079 | K5: Investigating | L5: 46338 | M5: botnet_cc; reporter Bitsight | N5: =IF(L5="","",IF(L5<TODAY(),"Expired","Active")) -> Active
A6: IOC-002 | B6: hxxps://x5u[.]6r6r6[.]org/a | C6: URL | D6: Vidar | E6: T1071 - Application Layer Protocol | F6: High | G6: High | H6: 46308 | I6: 46308 | J6: ThreatFox #1963078 | K6: Investigating | L6: 46338 | M6: botnet_cc; reporter Bitsight | N6: =IF(L6="","",IF(L6<TODAY(),"Expired","Active")) -> Active
A7: IOC-003 | B7: hxxps://x5u[.]6r6r6[.]org | C7: URL | D7: Vidar | E7: T1071 - Application Layer Protocol | F7: High | G7: High | H7: 46308 | I7: 46308 | J7: ThreatFox #1963077 | K7: Investigating | L7: 46338 | M7: botnet_cc; reporter Bitsight | N7: =IF(L7="","",IF(L7<TODAY(),"Expired","Active")) -> Active
A8: IOC-004 | B8: hxxps://y1[.]6r6r6[.]org/io/ | C8: URL | D8: Vidar | E8: T1071 - Application Layer Protocol | F8: High | G8: High | H8: 46308 | I8: 46308 | J8: ThreatFox #1963076 | K8: Investigating | L8: 46338 | M8: botnet_cc; reporter crep1x; compromised legitimate site | N8: =IF(L8="","",IF(L8<TODAY(),"Expired","Active")) -> Active
A9: IOC-005 | B9: hxxps://y1[.]6r6r6[.]org/gp | C9: URL | D9: Vidar | E9: T1071 - Application Layer Protocol | F9: High | G9: High | H9: 46308 | I9: 46308 | J9: ThreatFox #1963075 | K9: Investigating | L9: 46338 | M9: botnet_cc; reporter Bitsight | N9: =IF(L9="","",IF(L9<TODAY(),"Expired","Active")) -> Active
A10: IOC-006 | B10: hxxps://y1[.]6r6r6[.]org/i7p | C10: URL | D10: Vidar | E10: T1071 - Application Layer Protocol | F10: High | G10: High | H10: 46308 | I10: 46308 | J10: ThreatFox #1963074 | K10: Investigating | L10: 46338 | M10: botnet_cc; reporter Bitsight | N10: =IF(L10="","",IF(L10<TODAY(),"Expired","Active")) -> Active
A11: IOC-007 | B11: hxxps://y1[.]6r6r6[.]org/fx/ | C11: URL | D11: Vidar | E11: T1071 - Application Layer Protocol | F11: High | G11: High | H11: 46308 | I11: 46308 | J11: ThreatFox #1963073 | K11: Investigating | L11: 46338 | M11: botnet_cc; reporter crep1x; compromised legitimate site | N11: =IF(L11="","",IF(L11<TODAY(),"Expired","Active")) -> Active
A12: IOC-008 | B12: hxxps://y1[.]6r6r6[.]org/fx | C12: URL | D12: Vidar | E12: T1071 - Application Layer Protocol | F12: High | G12: High | H12: 46308 | I12: 46308 | J12: ThreatFox #1963072 | K12: Investigating | L12: 46338 | M12: botnet_cc; reporter Bitsight | N12: =IF(L12="","",IF(L12<TODAY(),"Expired","Active")) -> Active
A13: IOC-009 | B13: hxxps://y1[.]6r6r6[.]org/ux | C13: URL | D13: Vidar | E13: T1071 - Application Layer Protocol | F13: High | G13: High | H13: 46308 | I13: 46308 | J13: ThreatFox #1963071 | K13: Investigating | L13: 46338 | M13: botnet_cc; reporter Bitsight | N13: =IF(L13="","",IF(L13<TODAY(),"Expired","Active")) -> Active
A14: IOC-010 | B14: hxxps://y1[.]6r6r6[.]org/xc | C14: URL | D14: Vidar | E14: T1071 - Application Layer Protocol | F14: High | G14: High | H14: 46308 | I14: 46308 | J14: ThreatFox #1963070 | K14: Investigating | L14: 46338 | M14: botnet_cc; reporter Bitsight | N14: =IF(L14="","",IF(L14<TODAY(),"Expired","Active")) -> Active
A15: IOC-011 | B15: hxxps://y1[.]6r6r6[.]org/xc/ | C15: URL | D15: Vidar | E15: T1071 - Application Layer Protocol | F15: High | G15: High | H15: 46308 | I15: 46308 | J15: ThreatFox #1963069 | K15: Investigating | L15: 46338 | M15: botnet_cc; reporter crep1x; compromised legitimate site | N15: =IF(L15="","",IF(L15<TODAY(),"Expired","Active")) -> Active
A16: IOC-012 | B16: hxxps://y1[.]6r6r6[.]org/jg | C16: URL | D16: Vidar | E16: T1071 - Application Layer Protocol | F16: High | G16: High | H16: 46308 | I16: 46308 | J16: ThreatFox #1963068 | K16: Investigating | L16: 46338 | M16: botnet_cc; reporter Bitsight | N16: =IF(L16="","",IF(L16<TODAY(),"Expired","Active")) -> Active
... A60: IOC-056 | B60: hxxps://d4[.]6r6r6[.]org/ew | C60: URL | D60: Vidar | E60: T1071 - Application Layer Protocol | F60: High | G60: High | H60: 46308 | I60: 46308 | J60: ThreatFox #1963023 | K60: Investigating | L60: 46338 | M60: botnet_cc; reporter Bitsight | N60: =IF(L60="","",IF(L60<TODAY(),"Expired","Active")) -> Active
A61: IOC-057 | B61: db9581bf719943bb4085b2225abedb14f9a2b4cf562fe9c404821aec5a3363c2 | C61: File hash (SHA256) | D61: Mirai (alias Katana) | F61: High | G61: Medium | H61: 46308 | I61: 46308 | J61: ThreatFox #1963022 | K61: Investigating | L61: 46673 | M61: payload; reporter whack_sh | N61: =IF(L61="","",IF(L61<TODAY(),"Expired","Active")) -> Active
A62: IOC-058 | B62: hxxps://d4[.]6r6r6[.]org/e1b | C62: URL | D62: Vidar | E62: T1071 - Application Layer Protocol | F62: High | G62: High | H62: 46308 | I62: 46308 | J62: ThreatFox #1963021 | K62: Investigating | L62: 46338 | M62: botnet_cc; reporter Bitsight | N62: =IF(L62="","",IF(L62<TODAY(),"Expired","Active")) -> Active
A63: IOC-059 | B63: hxxps://d4[.]6r6r6[.]org/nr | C63: URL | D63: Vidar | E63: T1071 - Application Layer Protocol | F63: High | G63: High | H63: 46308 | I63: 46308 | J63: ThreatFox #1963020 | K63: Investigating | L63: 46338 | M63: botnet_cc; reporter Bitsight | N63: =IF(L63="","",IF(L63<TODAY(),"Expired","Active")) -> Active
A64: IOC-060 | B64: hxxps://d4[.]6r6r6[.]org/nr/ | C64: URL | D64: Vidar | E64: T1071 - Application Layer Protocol | F64: High | G64: High | H64: 46308 | I64: 46308 | J64: ThreatFox #1963019 | K64: Investigating | L64: 46338 | M64: botnet_cc; reporter crep1x; compromised legitimate site | N64: =IF(L64="","",IF(L64<TODAY(),"Expired","Active")) -> Active
A65: IOC-061 | B65: 147[.]182[.]144[.]201:8443 | C65: IPv4/IPv6 address | D65: Aisuru | E65: T1071 - Application Layer Protocol | F65: High | G65: Medium | H65: 46308 | I65: 46308 | J65: ThreatFox #1962805 | K65: Investigating | L65: 46338 | M65: botnet_cc (C2 server, IP:port) | N65: =IF(L65="","",IF(L65<TODAY(),"Expired","Active")) -> Active
A66: IOC-062 | B66: 120[.]76[.]143[.]184:8443 | C66: IPv4/IPv6 address | D66: Cobalt Strike | E66: T1071 - Application Layer Protocol | F66: High | G66: High | H66: 46308 | I66: 46308 | J66: ThreatFox #1962785 | K66: Investigating | L66: 46338 | M66: botnet_cc (C2 server, IP:port) | N66: =IF(L66="","",IF(L66<TODAY(),"Expired","Active")) -> Active
A67: IOC-063 | B67: 47[.]122[.]111[.]172:8080 | C67: IPv4/IPv6 address | D67: Cobalt Strike | E67: T1071 - Application Layer Protocol | F67: High | G67: High | H67: 46308 | I67: 46308 | J67: ThreatFox #1962784 | K67: Investigating | L67: 46338 | M67: botnet_cc (C2 server, IP:port) | N67: =IF(L67="","",IF(L67<TODAY(),"Expired","Active")) -> Active
A68: IOC-064 | B68: 47[.]236[.]199[.]243:7858 | C68: IPv4/IPv6 address | D68: Unknown malware | E68: T1071 - Application Layer Protocol | F68: Medium | G68: Medium | H68: 46308 | I68: 46308 | J68: ThreatFox #1962747 | K68: Investigating | L68: 46338 | M68: botnet_cc (C2 server, IP:port) | N68: =IF(L68="","",IF(L68<TODAY(),"Expired","Active")) -> Active
A69: IOC-065 | B69: 195[.]186[.]4[.]217:1705 | C69: IPv4/IPv6 address | D69: Unknown RAT | E69: T1071 - Application Layer Protocol | F69: Medium | G69: High | H69: 46308 | I69: 46308 | J69: ThreatFox #1962745 | K69: Investigating | L69: 46338 | M69: botnet_cc (C2 server, IP:port) | N69: =IF(L69="","",IF(L69<TODAY(),"Expired","Active")) -> Active
A70: IOC-066 | B70: 196[.]251[.]107[.]144:8082 | C70: IPv4/IPv6 address | D70: Unknown Stealer | E70: T1071 - Application Layer Protocol | F70: High | G70: High | H70: 46308 | I70: 46308 | J70: ThreatFox #1962721 | K70: Investigating | L70: 46338 | M70: botnet_cc (C2 server, IP:port) | N70: =IF(L70="","",IF(L70<TODAY(),"Expired","Active")) -> Active
A71: IOC-067 | B71: 60[.]217[.]58[.]49:56544 | C71: IPv4/IPv6 address | D71: Ghost RAT | E71: T1071 - Application Layer Protocol | F71: Low | G71: High | H71: 46308 | I71: 46308 | J71: ThreatFox #1962067 | K71: Investigating | L71: 46338 | M71: botnet_cc (C2 server, IP:port) | N71: =IF(L71="","",IF(L71<TODAY(),"Expired","Active")) -> Active
A72: IOC-068 | B72: 103[.]170[.]217[.]170:3912 | C72: IPv4/IPv6 address | D72: Mirai | E72: T1071 - Application Layer Protocol | F72: High | G72: Medium | H72: 46308 | I72: 46308 | J72: ThreatFox #1962438 | K72: Investigating | L72: 46338 | M72: botnet_cc (C2 server, IP:port) | N72: =IF(L72="","",IF(L72<TODAY(),"Expired","Active")) -> Active
A73: IOC-069 | B73: 82[.]165[.]128[.]60:7474 | C73: IPv4/IPv6 address | D73: Cobalt Strike | E73: T1071 - Application Layer Protocol | F73: Low | G73: High | H73: 46308 | I73: 46308 | J73: ThreatFox #1962514 | K73: Investigating | L73: 46338 | M73: botnet_cc (C2 server, IP:port) | N73: =IF(L73="","",IF(L73<TODAY(),"Expired","Active")) -> Active
... A94: IOC-090 | B94: 139[.]59[.]140[.]128:8080 | C94: IPv4/IPv6 address | D94: Aisuru | E94: T1071 - Application Layer Protocol | F94: High | G94: Medium | H94: 46308 | I94: 46308 | J94: ThreatFox #1962503 | K94: Investigating | L94: 46338 | M94: botnet_cc (C2 server, IP:port) | N94: =IF(L94="","",IF(L94<TODAY(),"Expired","Active")) -> Active
A95: IOC-091 | B95: da31eed9460cfdbb985f629672ebcefe5fa17b3ed1ff7bbe304aad13a89c2724 | C95: File hash (SHA256) | D95: Unclassified | F95: High | G95: Medium | H95: 46308 | I95: 46308 | J95: MalwareBazaar | K95: Investigating | L95: 46673 | M95: elf sample 'riscv64'; reporter abuse_ch | N95: =IF(L95="","",IF(L95<TODAY(),"Expired","Active")) -> Active
A96: IOC-092 | B96: 306bb9e9bd325d3a398f577f6666f114c15f9a3a | C96: File hash (SHA1) | D96: Unclassified | F96: High | G96: Medium | H96: 46308 | I96: 46308 | J96: MalwareBazaar | K96: Investigating | L96: 46673 | M96: elf sample 'riscv64'; reporter abuse_ch | N96: =IF(L96="","",IF(L96<TODAY(),"Expired","Active")) -> Active
A97: IOC-093 | B97: 034319c22e6486037acf609ce38facab | C97: File hash (MD5) | D97: Unclassified | F97: High | G97: Medium | H97: 46308 | I97: 46308 | J97: MalwareBazaar | K97: Investigating | L97: 46673 | M97: elf sample 'riscv64'; reporter abuse_ch | N97: =IF(L97="","",IF(L97<TODAY(),"Expired","Active")) -> Active
A98: IOC-094 | B98: d0e870e5b1c3455fa111c1a2f23827d5c972542fad51fb8f50e52a0a298013a7 | C98: File hash (SHA256) | D98: Mirai | F98: High | G98: Medium | H98: 46308 | I98: 46308 | J98: MalwareBazaar | K98: Investigating | L98: 46673 | M98: elf sample 'dissmpsl'; reporter abuse_ch | N98: =IF(L98="","",IF(L98<TODAY(),"Expired","Active")) -> Active
A99: IOC-095 | B99: c4c0275d997df8b75c1be17fc890b61b408ee5fe | C99: File hash (SHA1) | D99: Mirai | F99: High | G99: Medium | H99: 46308 | I99: 46308 | J99: MalwareBazaar | K99: Investigating | L99: 46673 | M99: elf sample 'dissmpsl'; reporter abuse_ch | N99: =IF(L99="","",IF(L99<TODAY(),"Expired","Active")) -> Active
A100: IOC-096 | B100: e8f0f86a56fb3624418049eaa442f029 | C100: File hash (MD5) | D100: Mirai | F100: High | G100: Medium | H100: 46308 | I100: 46308 | J100: MalwareBazaar | K100: Investigating | L100: 46673 | M100: elf sample 'dissmpsl'; reporter abuse_ch | N100: =IF(L100="","",IF(L100<TODAY(),"Expired","Active")) -> Active
A101: IOC-097 | B101: 2baaf219716c21543de54c9e51802b4e9970ea8bf43bbb01537abe15f4dd7e7d | C101: File hash (SHA256) | D101: RemcosRAT | E101: T1204.002 - Malicious File | F101: High | G101: High | H101: 46308 | I101: 46308 | J101: MalwareBazaar | K101: Investigating | L101: 46673 | M101: js sample 'FRA-9055D02-01951630-09-20260001.js'; reporter abuse_ch | N101: =IF(L101="","",IF(L101<TODAY(),"Expired","Active")) -> Active
A102: IOC-098 | B102: 41194dcbccbd83b6bc8718de780da04b8e560de8 | C102: File hash (SHA1) | D102: RemcosRAT | E102: T1204.002 - Malicious File | F102: High | G102: High | H102: 46308 | I102: 46308 | J102: MalwareBazaar | K102: Investigating | L102: 46673 | M102: js sample 'FRA-9055D02-01951630-09-20260001.js'; reporter abuse_ch | N102: =IF(L102="","",IF(L102<TODAY(),"Expired","Active")) -> Active
A103: IOC-099 | B103: dea0b31d6465e75168f9e57bc006fc3f | C103: File hash (MD5) | D103: RemcosRAT | E103: T1204.002 - Malicious File | F103: High | G103: High | H103: 46308 | I103: 46308 | J103: MalwareBazaar | K103: Investigating | L103: 46673 | M103: js sample 'FRA-9055D02-01951630-09-20260001.js'; reporter abuse_ch | N103: =IF(L103="","",IF(L103<TODAY(),"Expired","Active")) -> Active
A104: IOC-100 | B104: FRA-9055D02-01951630-09-20260001.js | C104: File name / path | D104: RemcosRAT | E104: T1204.002 - Malicious File | F104: Medium | G104: High | H104: 46308 | I104: 46308 | J104: MalwareBazaar | K104: Monitored | L104: 46398 | M104: Lure file name; SHA256 2baaf219716c... - names change easily, use for hunting not blocking | N104: =IF(L104="","",IF(L104<TODAY(),"Expired","Active")) -> Active
...

Sheet Summary
A1: IOC Summary
A3: Total IOCs | B3: =COUNTA('IOC Tracker'!B5:B280) -> 176
A4: Active | B4: =COUNTIF('IOC Tracker'!N5:N280,"Active") -> 171
A5: Expired (needs review) | B5: =COUNTIF('IOC Tracker'!N5:N280,"Expired") -> 5
A6: Critical severity | B6: =COUNTIF('IOC Tracker'!G5:G280,"Critical") -> 0
A7: High confidence | B7: =COUNTIF('IOC Tracker'!F5:F280,"High") -> 151
A8: Blocked | B8: =COUNTIF('IOC Tracker'!K5:K280,"Blocked") -> 0
A11: Count by IOC Type
A12: IPv4/IPv6 address | B12: =COUNTIF('IOC Tracker'!C5:C280,A12) -> 36
A13: Domain | B13: =COUNTIF('IOC Tracker'!C5:C280,A13) -> 5
A14: URL | B14: =COUNTIF('IOC Tracker'!C5:C280,A14) -> 53
A15: File hash (MD5) | B15: =COUNTIF('IOC Tracker'!C5:C280,A15) -> 25
A16: File hash (SHA1) | B16: =COUNTIF('IOC Tracker'!C5:C280,A16) -> 25
A17: File hash (SHA256) | B17: =COUNTIF('IOC Tracker'!C5:C280,A17) -> 26
A18: Email address | B18: =COUNTIF('IOC Tracker'!C5:C280,A18) -> 0
A19: Email subject / attachment | B19: =COUNTIF('IOC Tracker'!C5:C280,A19) -> 0
A20: File name / path | B20: =COUNTIF('IOC Tracker'!C5:C280,A20) -> 6
A21: Registry key | B21: =COUNTIF('IOC Tracker'!C5:C280,A21) -> 0
A22: Mutex | B22: =COUNTIF('IOC Tracker'!C5:C280,A22) -> 0
A23: User-agent string | B23: =COUNTIF('IOC Tracker'!C5:C280,A23) -> 0
A24: JA3/JA4 fingerprint | B24: =COUNTIF('IOC Tracker'!C5:C280,A24) -> 0
A25: SSL certificate hash | B25: =COUNTIF('IOC Tracker'!C5:C280,A25) -> 0
A26: ASN | B26: =COUNTIF('IOC Tracker'!C5:C280,A26) -> 0
A27: Crypto wallet | B27: =COUNTIF('IOC Tracker'!C5:C280,A27) -> 0
A29: Types showing 0 (email, registry, mutex, user-agent, JA3/JA4, SSL cert, ASN, crypto wallet) are not published in these free bulk feeds. They come from malware sandbox reports, phishing analysis, CISA/CERT-In advisories and your own incidents.
A30: Feed data pulled 2026-10-13. IP and URL indicators go stale within days to weeks; re-pull before relying on them.

Sheet Lists
A1: IPv4/IPv6 address | B1: High | C1: Critical | D1: Blocked
A2: Domain | B2: Medium | C2: High | D2: Monitored
A3: URL | B3: Low | C3: Medium | D3: Investigating
A4: File hash (MD5) | C4: Low | D4: Ignored
A5: File hash (SHA1) | D5: Expired
A6: File hash (SHA256)
A7: Email address
A8: Email subject / attachment
A9: File name / path
A10: Registry key
A11: Mutex
A12: User-agent string
A13: JA3/JA4 fingerprint
A14: SSL certificate hash
A15: ASN
A16: Crypto wallet

Sheet IOC Types
A1: IOC Type | B1: Example (safe placeholder) | C1: Notes
A2: IPv4/IPv6 address | B2: 203.0.113[.]45 | C2: C2 servers, scanners, exfiltration endpoints
A3: Domain | B3: update-check[.]example[.]com | C3: Phishing, C2, malware delivery
A4: URL | B4: hxxp://198.51.100[.]7/payload.exe | C4: Specific malicious paths
A5: File hash (MD5) | B5: d41d8cd98f00b204e9800998ecf8427e | C5: Fast but weak - prefer SHA256
A6: File hash (SHA1) | B6: da39a3ee5e6b4b0d3255bfef95601890afd80709 | C6: Legacy matching
A7: File hash (SHA256) | B7: e3b0c44298fc1c149afbf4c8996fb92427ae41e4649b934ca495991b7852b855 | C7: Standard for malware identification
A8: Email address | B8: billing@invoice-secure[.]example | C8: Phishing senders
A9: Email subject / attachment | B9: Invoice_Overdue.zip | C9: Phishing campaigns
A10: File name / path | B10: C:\Users\Public\svchost32.exe | C10: Masquerading binaries
A11: Registry key | B11: HKCU\Software\Microsoft\Windows\CurrentVersion\Run\Updater | C11: Persistence
A12: Mutex | B12: Global\XyZ_mtx_01 | C12: Malware-specific markers
... A17: Crypto wallet | B17: Wallet address | C17: Ransomware payments
A19: All examples use reserved documentation ranges (RFC 5737 IPs, RFC 5398 ASNs, example.com) or empty-input hashes. They are safe placeholders, not real threats.

Sheet Sources
A1: Source | B1: Provides | C1: URL
A2: abuse.ch MalwareBazaar | B2: Malware file hashes | C2: https://bazaar.abuse.ch
A3: abuse.ch URLhaus | B3: Malicious URLs | C3: https://urlhaus.abuse.ch
A4: abuse.ch ThreatFox | B4: Mixed IOCs (IPs, domains, hashes) | C4: https://threatfox.abuse.ch
A5: abuse.ch Feodo Tracker | B5: Botnet C2 IPs | C5: https://feodotracker.abuse.ch
A6: AlienVault OTX | B6: Community IOC 'pulses' by campaign | C6: https://otx.alienvault.com
A7: CISA Advisories (US) | B7: IOCs attached to official alerts | C7: https://www.cisa.gov/news-events/cybersecurity-advisories
A8: CERT-In (India) | B8: Indian national CERT advisories | C8: https://www.cert-in.org.in
A9: MISP | B9: Threat-intel sharing platform and feeds | C9: https://www.misp-project.org
A10: VirusTotal | B10: Check hashes, domains, IPs | C10: https://www.virustotal.com
A11: Spamhaus DROP | B11: Malicious IP ranges | C11: https://www.spamhaus.org/blocklists/do-not-route-or-peer/
